Workbook

Sheet 01_Data
A1: SECTION A — DAILY PRICE DATA
A2: DEF: Daily Price Data | O2: SECTION B — DAILY LOG RETURNS | AE2: SECTION C — MACRO INDICATORS | AY2: SECTION D — REGIME FLAGS | BE2: SECTION E — EVENT WINDOWS
A3: Date | B3: XOM | C3: CVX | D3: COP | E3: OXY | F3: LNG | G3: VG | H3: FRO | I3: STNG | J3: ET | K3: BIL | L3: WTI | M3: Brent | O3: Date | P3: r_XOM | Q3: r_CVX | R3: r_COP | S3: r_OXY | T3: r_LNG | U3: r_VG | V3: r_FRO | W3: r_STNG | X3: r_ET | Y3: r_BIL | Z3: r_SPY | AA3: r_WTI | AB3: r_Brent | AE3: Date | AF3: VIX | AG3: OVX | AH3: MOVE | AI3: Brent_WTI_Spread | AJ3: HenryHub | AK3: TTF | AL3: TTF_HH_Spread | AM3: FedFunds | AN3: DGS2 | AO3: DGS10 | AP3: Spread_2s10s | AQ3: T10YIE | AR3: DXY | AS3: Gold | AT3: CPI | AU3: IndProd | AV3: UMich | AY3: Date | AZ3: OVX_Stress | BA3: VIX_Stress | BB3: Conflict_Period | BE3: Date | BF3: Event_Label | BG3: Event_ID
A4: 43467 | B4: 50.0018 | C4: 80.6042 | D4: 49.3966 | E4: 52.7249 | F4: 57.5313 | H4: 3.3249 | I4: 15.9018 | J4: 7.0074 | K4: 75.929 | L4: 46.31 | M4: 54.06 | O4: 43467 | AE4: 43467 | AF4: 23.22 | AG4: 54.72 | AH4: 62.8 | AI4: =IF(AND(M4<>"",L4<>""),M4-L4,"") -> 7.75 | AJ4: 3.25 | AK4: 22.475 | AL4: =IF(AND(AK4<>"",AJ4<>""),AK4-AJ4,"") -> 19.225 | AM4: 2.4 | AN4: 2.5 | AO4: 2.66 | AP4: =IF(AND(AO4<>"",AN4<>""),AO4-AN4,"") -> 0.16 | AQ4: 1.7 | AR4: 115.7689 | AS4: 1281 | AY4: 43467 | AZ4: 0 | BA4: 0 | BB4: 0 | BE4: 43467 | BF4: Pre-COVID | BG4: 1
A5: 43468 | B5: 49.2341 | C5: 79.0605 | D5: 48.4614 | E5: 52.0786 | F5: 57.5982 | H5: 3.3544 | I5: 16.412 | J5: 7.055 | K5: 75.9539 | L5: 46.92 | M5: 53.23 | O5: 43468 | P5: =IF(AND(B5<>"",B4<>""),LN(B5/B4),"") -> -0.015472532 | Q5: =IF(AND(C5<>"",C4<>""),LN(C5/C4),"") -> -0.019337375 | R5: =IF(AND(D5<>"",D4<>""),LN(D5/D4),"") -> -0.019113991 | S5: =IF(AND(E5<>"",E4<>""),LN(E5/E4),"") -> -0.012333714 | T5: =IF(AND(F5<>"",F4<>""),LN(F5/F4),"") -> 0.0011621697 | U5: =IF(AND(G5<>"",G4<>""),LN(G5/G4),"") | V5: =IF(AND(H5<>"",H4<>""),LN(H5/H4),"") -> 0.0088333184 | W5: =IF(AND(I5<>"",I4<>""),LN(I5/I4),"") -> 0.031580464 | ... Y5: =IF(AND(K5<>"",K4<>""),LN(K5/K4),"") -> 0.00032788418 | Z5: -0.024152 | AA5: =IF(AND(L5<>"",L4<>""),LN(L5/L4),"") -> 0.013086103 | AB5: =IF(AND(M5<>"",M4<>""),LN(M5/M4),"") -> -0.015472394 | AE5: 43468 | AF5: 25.45 | AG5: 53.57 | AH5: 65.79 | AI5: =IF(AND(M5<>"",L5<>""),M5-L5,"") -> 6.31 | AJ5: 2.72 | AK5: 22.255 | AL5: =IF(AND(AK5<>"",AJ5<>""),AK5-AJ5,"") -> 19.535 | AM5: 2.4 | AN5: 2.39 | AO5: 2.56 | AP5: =IF(AND(AO5<>"",AN5<>""),AO5-AN5,"") -> 0.17 | AQ5: 1.68 | AR5: 115.4622 | AS5: 1291.8 | AY5: 43468 | AZ5: 0 | BA5: 0 | BB5: 0 | BE5: 43468 | BF5: Pre-COVID | BG5: 1
A6: 43469 | B6: 51.0494 | C6: 80.6989 | D6: 49.685 | E6: 53.7539 | F6: 59.0126 | H6: 3.5077 | I6: 17.0072 | J6: 7.4993 | K6: 75.9622 | L6: 47.76 | M6: 55.64 | O6: 43469 | P6: =IF(AND(B6<>"",B5<>""),LN(B6/B5),"") -> 0.036207319 | Q6: =IF(AND(C6<>"",C5<>""),LN(C6/C5),"") -> 0.020511562 | R6: =IF(AND(D6<>"",D5<>""),LN(D6/D5),"") -> 0.024935472 | S6: =IF(AND(E6<>"",E5<>""),LN(E6/E5),"") -> 0.031662107 | T6: =IF(AND(F6<>"",F5<>""),LN(F6/F5),"") -> 0.024259663 | U6: =IF(AND(G6<>"",G5<>""),LN(G6/G5),"") | V6: =IF(AND(H6<>"",H5<>""),LN(H6/H5),"") -> 0.044687635 | W6: =IF(AND(I6<>"",I5<>""),LN(I6/I5),"") -> 0.035624009 | ... Y6: =IF(AND(K6<>"",K5<>""),LN(K6/K5),"") -> 0.00010927084 | Z6: 0.032947 | AA6: =IF(AND(L6<>"",L5<>""),LN(L6/L5),"") -> 0.017744445 | AB6: =IF(AND(M6<>"",M5<>""),LN(M6/M5),"") -> 0.04428022 | AE6: 43469 | AF6: 21.38 | AG6: 51.52 | AH6: 65.82 | AI6: =IF(AND(M6<>"",L6<>""),M6-L6,"") -> 7.88 | AJ6: 2.8 | AK6: 22.93 | AL6: =IF(AND(AK6<>"",AJ6<>""),AK6-AJ6,"") -> 20.13 | AM6: 2.4 | AN6: 2.5 | AO6: 2.67 | AP6: =IF(AND(AO6<>"",AN6<>""),AO6-AN6,"") -> 0.17 | AQ6: 1.76 | AR6: 114.9821 | AS6: 1282.7 | AY6: 43469 | AZ6: 0 | BA6: 0 | BB6: 0 | BE6: 43469 | BF6: Pre-COVID | BG6: 1
A7: 43472 | B7: 51.3148 | C7: 81.7475 | D7: 49.4667 | E7: 54.8339 | F7: 59.7675 | H7: 3.5489 | I7: 17.3474 | J7: 7.6473 | K7: 75.9622 | L7: 48.27 | M7: 57.1 | O7: 43472 | P7: =IF(AND(B7<>"",B6<>""),LN(B7/B6),"") -> 0.0051854182 | Q7: =IF(AND(C7<>"",C6<>""),LN(C7/C6),"") -> 0.012910284 | R7: =IF(AND(D7<>"",D6<>""),LN(D7/D6),"") -> -0.0044033608 | S7: =IF(AND(E7<>"",E6<>""),LN(E7/E6),"") -> 0.019892393 | T7: =IF(AND(F7<>"",F6<>""),LN(F7/F6),"") -> 0.012711055 | U7: =IF(AND(G7<>"",G6<>""),LN(G7/G6),"") | V7: =IF(AND(H7<>"",H6<>""),LN(H7/H6),"") -> 0.011677144 | W7: =IF(AND(I7<>"",I6<>""),LN(I7/I6),"") -> 0.019805855 | ... Y7: =IF(AND(K7<>"",K6<>""),LN(K7/K6),"") -> 0 | Z7: 0.007854 | AA7: =IF(AND(L7<>"",L6<>""),LN(L7/L6),"") -> 0.010621781 | AB7: =IF(AND(M7<>"",M6<>""),LN(M7/M6),"") -> 0.02590175 | AE7: 43472 | AF7: 21.4 | AG7: 50.42 | AH7: 60.88 | AI7: =IF(AND(M7<>"",L7<>""),M7-L7,"") -> 8.83 | AJ7: 2.74 | AK7: 21.53 | AL7: =IF(AND(AK7<>"",AJ7<>""),AK7-AJ7,"") -> 18.79 | AM7: 2.4 | AN7: 2.53 | AO7: 2.7 | AP7: =IF(AND(AO7<>"",AN7<>""),AO7-AN7,"") -> 0.17 | AQ7: 1.78 | AR7: 114.5628 | AS7: 1286.8 | AY7: 43472 | AZ7: 0 | BA7: 0 | BB7: 0 | BE7: 43472 | BF7: Pre-COVID | BG7: 1
A8: 43473 | B8: 51.688 | C8: 81.3907 | D8: 50.1292 | E8: 55.2676 | F8: 61.5164 | H8: 3.6197 | I8: 17.3474 | J8: 7.8166 | K8: 75.9622 | L8: 49.58 | M8: 56.91 | O8: 43473 | P8: =IF(AND(B8<>"",B7<>""),LN(B8/B7),"") -> 0.0072464367 | Q8: =IF(AND(C8<>"",C7<>""),LN(C8/C7),"") -> -0.0043742124 | R8: =IF(AND(D8<>"",D7<>""),LN(D8/D7),"") -> 0.013303957 | S8: =IF(AND(E8<>"",E7<>""),LN(E8/E7),"") -> 0.0078782259 | T8: =IF(AND(F8<>"",F7<>""),LN(F8/F7),"") -> 0.028841771 | U8: =IF(AND(G8<>"",G7<>""),LN(G8/G7),"") | V8: =IF(AND(H8<>"",H7<>""),LN(H8/H7),"") -> 0.019753453 | W8: =IF(AND(I8<>"",I7<>""),LN(I8/I7),"") -> 0 | ... Y8: =IF(AND(K8<>"",K7<>""),LN(K8/K7),"") -> 0 | Z8: 0.009351 | AA8: =IF(AND(L8<>"",L7<>""),LN(L8/L7),"") -> 0.026777277 | AB8: =IF(AND(M8<>"",M7<>""),LN(M8/M7),"") -> -0.003333044 | AE8: 43473 | AF8: 20.47 | AG8: 46.08 | AH8: 59.05 | AI8: =IF(AND(M8<>"",L8<>""),M8-L8,"") -> 7.33 | AJ8: 2.89 | AK8: 22.09 | AL8: =IF(AND(AK8<>"",AJ8<>""),AK8-AJ8,"") -> 19.2 | AM8: 2.4 | AN8: 2.58 | AO8: 2.73 | AP8: =IF(AND(AO8<>"",AN8<>""),AO8-AN8,"") -> 0.15 | AQ8: 1.82 | AR8: 114.7281 | AS8: 1283.2 | AY8: 43473 | AZ8: 0 | BA8: 0 | BB8: 0 | BE8: 43473 | BF8: Pre-COVID | BG8: 1
A9: 43474 | B9: 51.9606 | C9: 82.483 | D9: 51.7893 | E9: 55.9394 | F9: 62.1854 | H9: 3.6786 | I9: 17.1773 | J9: 7.9911 | K9: 75.9622 | L9: 52.19 | M9: 59.46 | O9: 43474 | P9: =IF(AND(B9<>"",B8<>""),LN(B9/B8),"") -> 0.0052600928 | Q9: =IF(AND(C9<>"",C8<>""),LN(C9/C8),"") -> 0.013331196 | R9: =IF(AND(D9<>"",D8<>""),LN(D9/D8),"") -> 0.032579892 | S9: =IF(AND(E9<>"",E8<>""),LN(E9/E8),"") -> 0.01208212 | T9: =IF(AND(F9<>"",F8<>""),LN(F9/F8),"") -> 0.01081644 | U9: =IF(AND(G9<>"",G8<>""),LN(G9/G8),"") | V9: =IF(AND(H9<>"",H8<>""),LN(H9/H8),"") -> 0.016141096 | W9: =IF(AND(I9<>"",I8<>""),LN(I9/I8),"") -> -0.0098538945 | ... Y9: =IF(AND(K9<>"",K8<>""),LN(K9/K8),"") -> 0 | Z9: 0.004663 | AA9: =IF(AND(L9<>"",L8<>""),LN(L9/L8),"") -> 0.051303379 | AB9: =IF(AND(M9<>"",M8<>""),LN(M9/M8),"") -> 0.043832745 | AE9: 43474 | AF9: 19.98 | AG9: 44.36 | AH9: 57.02 | AI9: =IF(AND(M9<>"",L9<>""),M9-L9,"") -> 7.27 | AJ9: 2.92 | AK9: 21.72 | AL9: =IF(AND(AK9<>"",AJ9<>""),AK9-AJ9,"") -> 18.8 | AM9: 2.4 | AN9: 2.56 | AO9: 2.74 | AP9: =IF(AND(AO9<>"",AN9<>""),AO9-AN9,"") -> 0.18 | AQ9: 1.83 | AR9: 114.1406 | AS9: 1289.3 | AY9: 43474 | AZ9: 0 | BA9: 0 | BB9: 0 | BE9: 43474 | BF9: Pre-COVID | BG9: 1
A10: 43475 | B10: 51.6951 | C10: 82.6141 | D10: 52.9505 | E10: 56.2881 | F10: 62.797 | H10: 3.4251 | I10: 17.0923 | J10: 7.9858 | K10: 75.9705 | L10: 52.42 | M10: 60.47 | O10: 43475 | P10: =IF(AND(B10<>"",B9<>""),LN(B10/B9),"") -> -0.0051227396 | Q10: =IF(AND(C10<>"",C9<>""),LN(C10/C9),"") -> 0.0015881566 | R10: =IF(AND(D10<>"",D9<>""),LN(D10/D9),"") -> 0.022173951 | S10: =IF(AND(E10<>"",E9<>""),LN(E10/E9),"") -> 0.0062141832 | T10: =IF(AND(F10<>"",F9<>""),LN(F10/F9),"") -> 0.0097870561 | U10: =IF(AND(G10<>"",G9<>""),LN(G10/G9),"") | V10: =IF(AND(H10<>"",H9<>""),LN(H10/H9),"") -> -0.071401577 | W10: =IF(AND(I10<>"",I9<>""),LN(I10/I9),"") -> -0.004960675 | ... Y10: =IF(AND(K10<>"",K9<>""),LN(K10/K9),"") -> 0.0001092589 | Z10: 0.003521 | AA10: =IF(AND(L10<>"",L9<>""),LN(L10/L9),"") -> 0.0043972922 | AB10: =IF(AND(M10<>"",M9<>""),LN(M10/M9),"") -> 0.016843557 | AE10: 43475 | AF10: 19.5 | AG10: 42.99 | AH10: 56.65 | AI10: =IF(AND(M10<>"",L10<>""),M10-L10,"") -> 8.05 | AJ10: 2.95 | AK10: 21.675 | AL10: =IF(AND(AK10<>"",AJ10<>""),AK10-AJ10,"") -> 18.725 | AM10: 2.4 | AN10: 2.56 | AO10: 2.74 | AP10: =IF(AND(AO10<>"",AN10<>""),AO10-AN10,"") -> 0.18 | AQ10: 1.81 | AR10: 114.0496 | AS10: 1284.7 | AY10: 43475 | AZ10: 0 | BA10: 0 | BB10: 0 | BE10: 43475 | BF10: Pre-COVID | BG10: 1
A11: 43476 | B11: 51.4584 | C11: 81.9514 | D11: 51.7425 | E11: 56.3136 | F11: 61.6406 | H11: 3.3072 | I11: 16.8372 | J11: 7.9541 | K11: 75.9871 | L11: 51.44 | M11: 59.24 | O11: 43476 | P11: =IF(AND(B11<>"",B10<>""),LN(B11/B10),"") -> -0.0045892852 | Q11: =IF(AND(C11<>"",C10<>""),LN(C11/C10),"") -> -0.0080539795 | R11: =IF(AND(D11<>"",D10<>""),LN(D11/D10),"") -> -0.023078021 | S11: =IF(AND(E11<>"",E10<>""),LN(E11/E10),"") -> 0.0004529239 | T11: =IF(AND(F11<>"",F10<>""),LN(F11/F10),"") -> -0.018586557 | U11: =IF(AND(G11<>"",G10<>""),LN(G11/G10),"") | V11: =IF(AND(H11<>"",H10<>""),LN(H11/H10),"") -> -0.035028758 | W11: =IF(AND(I11<>"",I10<>""),LN(I11/I10),"") -> -0.015037345 | ... Y11: =IF(AND(K11<>"",K10<>""),LN(K11/K10),"") -> 0.000218482 | Z11: 0.000386 | AA11: =IF(AND(L11<>"",L10<>""),LN(L11/L10),"") -> -0.018872118 | AB11: =IF(AND(M11<>"",M10<>""),LN(M11/M10),"") -> -0.020550385 | AE11: 43476 | AF11: 18.19 | AG11: 40.99 | AH11: 55.94 | AI11: =IF(AND(M11<>"",L11<>""),M11-L11,"") -> 7.8 | AJ11: 2.95 | AK11: 22.255 | AL11: =IF(AND(AK11<>"",AJ11<>""),AK11-AJ11,"") -> 19.305 | AM11: 2.4 | AN11: 2.55 | AO11: 2.71 | AP11: =IF(AND(AO11<>"",AN11<>""),AO11-AN11,"") -> 0.16 | AQ11: 1.83 | AR11: 114.0404 | AS11: 1287.1 | AY11: 43476 | AZ11: 0 | BA11: 0 | BB11: 0 | BE11: 43476 | BF11: Pre-COVID | BG11: 1
A12: 43479 | B12: 51.3938 | C12: 81.3543 | D12: 51.1346 | E12: 55.7693 | F12: 61.6406 | H12: 3.2306 | I12: 16.497 | J12: 7.7796 | K12: 75.9788 | L12: 50.31 | M12: 58.8 | O12: 43479 | P12: =IF(AND(B12<>"",B11<>""),LN(B12/B11),"") -> -0.0012561716 | Q12: =IF(AND(C12<>"",C11<>""),LN(C12/C11),"") -> -0.0073126983 | R12: =IF(AND(D12<>"",D11<>""),LN(D12/D11),"") -> -0.011818122 | S12: =IF(AND(E12<>"",E11<>""),LN(E12/E11),"") -> -0.0097125303 | T12: =IF(AND(F12<>"",F11<>""),LN(F12/F11),"") -> 0 | U12: =IF(AND(G12<>"",G11<>""),LN(G12/G11),"") | V12: =IF(AND(H12<>"",H11<>""),LN(H12/H11),"") -> -0.023434031 | W12: =IF(AND(I12<>"",I11<>""),LN(I12/I11),"") -> -0.020412178 | ... Y12: =IF(AND(K12<>"",K11<>""),LN(K12/K11),"") -> -0.00010923503 | Z12: -0.00612 | AA12: =IF(AND(L12<>"",L11<>""),LN(L12/L11),"") -> -0.022212215 | AB12: =IF(AND(M12<>"",M11<>""),LN(M12/M11),"") -> -0.0074551345 | AE12: 43479 | AF12: 19.07 | AG12: 40.81 | AH12: 55.34 | AI12: =IF(AND(M12<>"",L12<>""),M12-L12,"") -> 8.49 | AJ12: 3.36 | AK12: 21.675 | AL12: =IF(AND(AK12<>"",AJ12<>""),AK12-AJ12,"") -> 18.315 | AM12: 2.4 | AN12: 2.53 | AO12: 2.71 | AP12: =IF(AND(AO12<>"",AN12<>""),AO12-AN12,"") -> 0.18 | AQ12: 1.81 | AS12: 1289.1 | AY12: 43479 | AZ12: 0 | BA12: 0 | BB12: 0 | BE12: 43479 | BF12: Pre-COVID | BG12: 1
A13: 43480 | B13: 51.4225 | C13: 81.6456 | D13: 51.4619 | E13: 55.7183 | F13: 62.0133 | H13: 3.3367 | I13: 16.9222 | J13: 7.8642 | K13: 75.9954 | L13: 51.8 | M13: 58.65 | O13: 43480 | P13: =IF(AND(B13<>"",B12<>""),LN(B13/B12),"") -> 0.00055827725 | Q13: =IF(AND(C13<>"",C12<>""),LN(C13/C12),"") -> 0.0035742391 | R13: =IF(AND(D13<>"",D12<>""),LN(D13/D12),"") -> 0.0063803563 | S13: =IF(AND(E13<>"",E12<>""),LN(E13/E12),"") -> -0.00091490002 | T13: =IF(AND(F13<>"",F12<>""),LN(F13/F12),"") -> 0.0060281338 | U13: =IF(AND(G13<>"",G12<>""),LN(G13/G12),"") | V13: =IF(AND(H13<>"",H12<>""),LN(H13/H12),"") -> 0.032314416 | W13: =IF(AND(I13<>"",I12<>""),LN(I13/I12),"") -> 0.025447823 | ... Y13: =IF(AND(K13<>"",K12<>""),LN(K13/K12),"") -> 0.00021845813 | Z13: 0.011396 | AA13: =IF(AND(L13<>"",L12<>""),LN(L13/L12),"") -> 0.029186285 | AB13: =IF(AND(M13<>"",M12<>""),LN(M13/M12),"") -> -0.0025542798 | AE13: 43480 | AF13: 18.6 | AG13: 39.75 | AH13: 53.01 | AI13: =IF(AND(M13<>"",L13<>""),M13-L13,"") -> 6.85 | AJ13: 3.54 | AK13: 22 | AL13: =IF(AND(AK13<>"",AJ13<>""),AK13-AJ13,"") -> 18.46 | AM13: 2.4 | AN13: 2.53 | AO13: 2.72 | AP13: =IF(AND(AO13<>"",AN13<>""),AO13-AN13,"") -> 0.19 | AQ13: 1.81 | AR13: 114.3402 | AS13: 1286.2 | AY13: 43480 | AZ13: 0 | BA13: 0 | BB13: 0 | BE13: 43480 | BF13: Pre-COVID | BG13: 1
A14: 43481 | B14: 51.4009 | C14: 81.1213 | D14: 51.1736 | E14: 55.3951 | F14: 60.9143 | H14: 3.2836 | I14: 16.327 | J14: 7.7478 | K14: 76.0037 | L14: 52.08 | M14: 59.81 | O14: 43481 | P14: =IF(AND(B14<>"",B13<>""),LN(B14/B13),"") -> -0.00042013783 | Q14: =IF(AND(C14<>"",C13<>""),LN(C14/C13),"") -> -0.0064423641 | R14: =IF(AND(D14<>"",D13<>""),LN(D14/D13),"") -> -0.005617954 | S14: =IF(AND(E14<>"",E13<>""),LN(E14/E13),"") -> -0.0058174966 | T14: =IF(AND(F14<>"",F13<>""),LN(F14/F13),"") -> -0.01788092 | U14: =IF(AND(G14<>"",G13<>""),LN(G14/G13),"") | V14: =IF(AND(H14<>"",H13<>""),LN(H14/H13),"") -> -0.016041913 | W14: =IF(AND(I14<>"",I13<>""),LN(I14/I13),"") -> -0.03580619 | ... Y14: =IF(AND(K14<>"",K13<>""),LN(K14/K13),"") -> 0.00010921117 | Z14: 0.002417 | AA14: =IF(AND(L14<>"",L13<>""),LN(L14/L13),"") -> 0.0053908486 | AB14: =IF(AND(M14<>"",M13<>""),LN(M14/M13),"") -> 0.019585296 | AE14: 43481 | AF14: 19.04 | AG14: 38.77 | AH14: 51.95 | AI14: =IF(AND(M14<>"",L14<>""),M14-L14,"") -> 7.73 | AJ14: 3.58 | AK14: 22.005 | AL14: =IF(AND(AK14<>"",AJ14<>""),AK14-AJ14,"") -> 18.425 | AM14: 2.4 | AN14: 2.55 | AO14: 2.73 | AP14: =IF(AND(AO14<>"",AN14<>""),AO14-AN14,"") -> 0.18 | AQ14: 1.82 | AR14: 114.137 | AS14: 1291.6 | AY14: 43481 | AZ14: 0 | BA14: 0 | BB14: 0 | BE14: 43481 | BF14: Pre-COVID | BG14: 1
A15: 43482 | B15: 51.7525 | C15: 81.5291 | D15: 52.2647 | E15: 55.9819 | F15: 61.1819 | H15: 3.3072 | I15: 16.8372 | J15: 7.7267 | K15: 76.0203 | L15: 51.83 | M15: 59.85 | O15: 43482 | P15: =IF(AND(B15<>"",B14<>""),LN(B15/B14),"") -> 0.0068170581 | Q15: =IF(AND(C15<>"",C14<>""),LN(C15/C14),"") -> 0.0050144464 | R15: =IF(AND(D15<>"",D14<>""),LN(D15/D14),"") -> 0.021097417 | S15: =IF(AND(E15<>"",E14<>""),LN(E15/E14),"") -> 0.010537282 | T15: =IF(AND(F15<>"",F14<>""),LN(F15/F14),"") -> 0.0043834358 | U15: =IF(AND(G15<>"",G14<>""),LN(G15/G14),"") | V15: =IF(AND(H15<>"",H14<>""),LN(H15/H14),"") -> 0.0071615285 | W15: =IF(AND(I15<>"",I14<>""),LN(I15/I14),"") -> 0.030770545 | ... Y15: =IF(AND(K15<>"",K14<>""),LN(K15/K14),"") -> 0.00021838657 | Z15: 0.007558 | AA15: =IF(AND(L15<>"",L14<>""),LN(L15/L14),"") -> -0.0048118657 | AB15: =IF(AND(M15<>"",M14<>""),LN(M15/M14),"") -> 0.00066856095 | AE15: 43482 | AF15: 18.06 | AG15: 37.03 | AH15: 53.44 | AI15: =IF(AND(M15<>"",L15<>""),M15-L15,"") -> 8.02 | AJ15: 3.58 | AK15: 22.995 | AL15: =IF(AND(AK15<>"",AJ15<>""),AK15-AJ15,"") -> 19.415 | AM15: 2.4 | AN15: 2.56 | AO15: 2.75 | AP15: =IF(AND(AO15<>"",AN15<>""),AO15-AN15,"") -> 0.19 | AQ15: 1.79 | AR15: 114.4115 | AS15: 1291 | AY15: 43482 | AZ15: 0 | BA15: 0 | BB15: 0 | BE15: 43482 | BF15: Pre-COVID | BG15: 1
A16: 43483 | B16: 52.3696 | C16: 83.284 | D16: 52.9194 | E16: 57.0024 | F16: 61.9273 | H16: 3.4192 | I16: 17.9001 | J16: 7.7055 | K16: 76.0203 | L16: 53.6 | M16: 62.04 | O16: 43483 | P16: =IF(AND(B16<>"",B15<>""),LN(B16/B15),"") -> 0.01185353 | Q16: =IF(AND(C16<>"",C15<>""),LN(C16/C15),"") -> 0.021296442 | R16: =IF(AND(D16<>"",D15<>""),LN(D16/D15),"") -> 0.01244881 | S16: =IF(AND(E16<>"",E15<>""),LN(E16/E15),"") -> 0.018064948 | T16: =IF(AND(F16<>"",F15<>""),LN(F16/F15),"") -> 0.012109722 | U16: =IF(AND(G16<>"",G15<>""),LN(G16/G15),"") | V16: =IF(AND(H16<>"",H15<>""),LN(H16/H15),"") -> 0.033304696 | W16: =IF(AND(I16<>"",I15<>""),LN(I16/I15),"") -> 0.061215575 | ... Y16: =IF(AND(K16<>"",K15<>""),LN(K16/K15),"") -> 0 | Z16: 0.013222 | AA16: =IF(AND(L16<>"",L15<>""),LN(L16/L15),"") -> 0.033579936 | AB16: =IF(AND(M16<>"",M15<>""),LN(M16/M15),"") -> 0.035937906 | AE16: 43483 | AF16: 17.8 | AG16: 35.63 | AH16: 53.78 | AI16: =IF(AND(M16<>"",L16<>""),M16-L16,"") -> 8.44 | AJ16: 3.43 | AK16: 22.605 | AL16: =IF(AND(AK16<>"",AJ16<>""),AK16-AJ16,"") -> 19.175 | AM16: 2.4 | AN16: 2.62 | AO16: 2.79 | AP16: =IF(AND(AO16<>"",AN16<>""),AO16-AN16,"") -> 0.17 | AQ16: 1.83 | AR16: 114.558 | AS16: 1281.3 | AY16: 43483 | AZ16: 0 | BA16: 0 | BB16: 0 | BE16: 43483 | BF16: Pre-COVID | BG16: 1
A17: 43487 | B17: 51.5803 | C17: 81.8058 | D17: 51.2437 | E17: 55.3781 | F17: 60.2263 | H17: 3.3249 | I17: 17.0328 | J17: 7.457 | K17: 76.0286 | L17: 52.59 | M17: 60.9 | O17: 43487 | P17: =IF(AND(B17<>"",B16<>""),LN(B17/B16),"") -> -0.015186454 | Q17: =IF(AND(C17<>"",C16<>""),LN(C17/C16),"") -> -0.017908308 | R17: =IF(AND(D17<>"",D16<>""),LN(D17/D16),"") -> -0.032177318 | S17: =IF(AND(E17<>"",E16<>""),LN(E17/E16),"") -> -0.028909163 | T17: =IF(AND(F17<>"",F16<>""),LN(F17/F16),"") -> -0.027851982 | U17: =IF(AND(G17<>"",G16<>""),LN(G17/G16),"") | V17: =IF(AND(H17<>"",H16<>""),LN(H17/H16),"") -> -0.027967007 | W17: =IF(AND(I17<>"",I16<>""),LN(I17/I16),"") -> -0.049665403 | ... Y17: =IF(AND(K17<>"",K16<>""),LN(K17/K16),"") -> 0.0001091754 | Z17: -0.013602 | AA17: =IF(AND(L17<>"",L16<>""),LN(L17/L16),"") -> -0.01902308 | AB17: =IF(AND(M17<>"",M16<>""),LN(M17/M16),"") -> -0.018546164 | AE17: 43487 | AF17: 20.8 | AG17: 38.26 | AH17: 54.64 | AI17: =IF(AND(M17<>"",L17<>""),M17-L17,"") -> 8.31 | AJ17: 3.43 | AK17: 21.815 | AL17: =IF(AND(AK17<>"",AJ17<>""),AK17-AJ17,"") -> 18.385 | AM17: 2.4 | AN17: 2.58 | AO17: 2.74 | AP17: =IF(AND(AO17<>"",AN17<>""),AO17-AN17,"") -> 0.16 | AQ17: 1.79 | AR17: 114.7541 | AS17: 1282.5 | AY17: 43487 | AZ17: 0 | BA17: 0 | BB17: 0 | BE17: 43487 | BF17: Pre-COVID | BG17: 1
A18: 43488 | B18: 51.157 | C18: 81.114 | D18: 51.3294 | E18: 54.9104 | F18: 59.9491 | H18: 3.3308 | I18: 16.9052 | J18: 7.4252 | K18: 76.0286 | L18: 52.44 | M18: 61.05 | O18: 43488 | P18: =IF(AND(B18<>"",B17<>""),LN(B18/B17),"") -> -0.0082404812 | Q18: =IF(AND(C18<>"",C17<>""),LN(C18/C17),"") -> -0.0084925731 | R18: =IF(AND(D18<>"",D17<>""),LN(D18/D17),"") -> 0.0016710038 | S18: =IF(AND(E18<>"",E17<>""),LN(E18/E17),"") -> -0.0084814428 | T18: =IF(AND(F18<>"",F17<>""),LN(F18/F17),"") -> -0.0046132651 | U18: =IF(AND(G18<>"",G17<>""),LN(G18/G17),"") | V18: =IF(AND(H18<>"",H17<>""),LN(H18/H17),"") -> 0.0017729169 | W18: =IF(AND(I18<>"",I17<>""),LN(I18/I17),"") -> -0.00751963 | ... Y18: =IF(AND(K18<>"",K17<>""),LN(K18/K17),"") -> 0 | Z18: 0.00209 | AA18: =IF(AND(L18<>"",L17<>""),LN(L18/L17),"") -> -0.0028563287 | AB18: =IF(AND(M18<>"",M17<>""),LN(M18/M17),"") -> 0.0024600258 | AE18: 43488 | AF18: 19.52 | AG18: 37.69 | AH18: 54.19 | AI18: =IF(AND(M18<>"",L18<>""),M18-L18,"") -> 8.61 | AJ18: 3.13 | AK18: 22.19 | AL18: =IF(AND(AK18<>"",AJ18<>""),AK18-AJ18,"") -> 19.06 | AM18: 2.4 | AN18: 2.58 | AO18: 2.76 | AP18: =IF(AND(AO18<>"",AN18<>""),AO18-AN18,"") -> 0.18 | AQ18: 1.8 | AR18: 114.5759 | AS18: 1283.1 | AY18: 43488 | AZ18: 0 | BA18: 0 | BB18: 0 | BE18: 43488 | BF18: Pre-COVID | BG18: 1
A19: 43489 | B19: 51.2287 | C19: 82.6578 | D19: 51.5321 | E19: 55.2591 | F19: 60.4174 | H19: 3.2954 | I19: 17.1773 | J19: 7.4675 | K19: 76.0535 | L19: 52.94 | M19: 61.09 | O19: 43489 | P19: =IF(AND(B19<>"",B18<>""),LN(B19/B18),"") -> 0.0014005864 | Q19: =IF(AND(C19<>"",C18<>""),LN(C19/C18),"") -> 0.018853621 | R19: =IF(AND(D19<>"",D18<>""),LN(D19/D18),"") -> 0.003941227 | S19: =IF(AND(E19<>"",E18<>""),LN(E19/E18),"") -> 0.0063302668 | T19: =IF(AND(F19<>"",F18<>""),LN(F19/F18),"") -> 0.0077812741 | U19: =IF(AND(G19<>"",G18<>""),LN(G19/G18),"") | V19: =IF(AND(H19<>"",H18<>""),LN(H19/H18),"") -> -0.010684959 | W19: =IF(AND(I19<>"",I18<>""),LN(I19/I18),"") -> 0.015967478 | ... Y19: =IF(AND(K19<>"",K18<>""),LN(K19/K18),"") -> 0.00032745471 | Z19: 0.000531 | AA19: =IF(AND(L19<>"",L18<>""),LN(L19/L18),"") -> 0.0094895379 | AB19: =IF(AND(M19<>"",M18<>""),LN(M19/M18),"") -> 0.0006549861 | AE19: 43489 | AF19: 18.89 | AG19: 36.75 | AH19: 54.18 | AI19: =IF(AND(M19<>"",L19<>""),M19-L19,"") -> 8.15 | AJ19: 3.13 | AK19: 21.28 | AL19: =IF(AND(AK19<>"",AJ19<>""),AK19-AJ19,"") -> 18.15 | AM19: 2.4 | AN19: 2.56 | AO19: 2.72 | AP19: =IF(AND(AO19<>"",AN19<>""),AO19-AN19,"") -> 0.16 | AQ19: 1.77 | AR19: 114.617 | AS19: 1279.1 | AY19: 43489 | AZ19: 0 | BA19: 0 | BB19: 0 | BE19: 43489 | BF19: Pre-COVID | BG19: 1
A20: 43490 | B20: 51.4584 | C20: 82.4466 | D20: 52.2101 | E20: 56.5772 | F20: 60.7328 | H20: 3.2188 | I20: 17.3729 | J20: 7.5839 | K20: 76.0452 | L20: 53.53 | M20: 61.49 | O20: 43490 | P20: =IF(AND(B20<>"",B19<>""),LN(B20/B19),"") -> 0.0044737924 | Q20: =IF(AND(C20<>"",C19<>""),LN(C20/C19),"") -> -0.0025583826 | R20: =IF(AND(D20<>"",D19<>""),LN(D20/D19),"") -> 0.013071048 | S20: =IF(AND(E20<>"",E19<>""),LN(E20/E19),"") -> 0.023573044 | T20: =IF(AND(F20<>"",F19<>""),LN(F20/F19),"") -> 0.0052067716 | U20: =IF(AND(G20<>"",G19<>""),LN(G20/G19),"") | V20: =IF(AND(H20<>"",H19<>""),LN(H20/H19),"") -> -0.023518937 | W20: =IF(AND(I20<>"",I19<>""),LN(I20/I19),"") -> 0.011322776 | ... Y20: =IF(AND(K20<>"",K19<>""),LN(K20/K19),"") -> -0.00010913966 | Z20: 0.008426 | AA20: =IF(AND(L20<>"",L19<>""),LN(L20/L19),"") -> 0.011083048 | AB20: =IF(AND(M20<>"",M19<>""),LN(M20/M19),"") -> 0.0065263733 | AE20: 43490 | AF20: 17.42 | AG20: 35.21 | AH20: 52.5 | AI20: =IF(AND(M20<>"",L20<>""),M20-L20,"") -> 7.96 | AJ20: 3.07 | AK20: 20.89 | AL20: =IF(AND(AK20<>"",AJ20<>""),AK20-AJ20,"") -> 17.82 | AM20: 2.4 | AN20: 2.6 | AO20: 2.76 | AP20: =IF(AND(AO20<>"",AN20<>""),AO20-AN20,"") -> 0.16 | AQ20: 1.79 | AR20: 114.0197 | AS20: 1297.4 | AY20: 43490 | AZ20: 0 | BA20: 0 | BB20: 0 | BE20: 43490 | BF20: Pre-COVID | BG20: 1
A21: 43493 | B21: 51.1139 | C21: 81.682 | D21: 50.932 | E21: 56.1945 | F21: 62.3669 | H21: 3.0714 | I21: 17.2709 | J21: 7.5098 | K21: 76.0535 | L21: 51.79 | M21: 59.71 | O21: 43493 | P21: =IF(AND(B21<>"",B20<>""),LN(B21/B20),"") -> -0.0067172384 | Q21: =IF(AND(C21<>"",C20<>""),LN(C21/C20),"") -> -0.0093171517 | R21: =IF(AND(D21<>"",D20<>""),LN(D21/D20),"") -> -0.024784553 | S21: =IF(AND(E21<>"",E20<>""),LN(E21/E20),"") -> -0.0067871899 | T21: =IF(AND(F21<>"",F20<>""),LN(F21/F20),"") -> 0.026550771 | U21: =IF(AND(G21<>"",G20<>""),LN(G21/G20),"") | V21: =IF(AND(H21<>"",H20<>""),LN(H21/H20),"") -> -0.046875136 | W21: =IF(AND(I21<>"",I20<>""),LN(I21/I20),"") -> -0.0058885165 | ... Y21: =IF(AND(K21<>"",K20<>""),LN(K21/K20),"") -> 0.00010913966 | Z21: -0.007629 | AA21: =IF(AND(L21<>"",L20<>""),LN(L21/L20),"") -> -0.033045164 | AB21: =IF(AND(M21<>"",M20<>""),LN(M21/M20),"") -> -0.029375049 | AE21: 43493 | AF21: 18.87 | AG21: 37.61 | AH21: 50.95 | AI21: =IF(AND(M21<>"",L21<>""),M21-L21,"") -> 7.92 | AJ21: 3.05 | AK21: 20.55 | AL21: =IF(AND(AK21<>"",AJ21<>""),AK21-AJ21,"") -> 17.5 | AM21: 2.4 | AN21: 2.6 | AO21: 2.75 | AP21: =IF(AND(AO21<>"",AN21<>""),AO21-AN21,"") -> 0.15 | AQ21: 1.78 | AR21: 114.0522 | AS21: 1302.4 | AY21: 43493 | AZ21: 0 | BA21: 0 | BB21: 0 | BE21: 43493 | BF21: Pre-COVID | BG21: 1
A22: 43494 | B22: 51.3077 | C22: 81.4344 | D22: 50.893 | E22: 56.5347 | F22: 62.5008 | H22: 3.0714 | I22: 17.0668 | J22: 7.5522 | K22: 76.0535 | L22: 53.07 | M22: 60.98 | O22: 43494 | P22: =IF(AND(B22<>"",B21<>""),LN(B22/B21),"") -> 0.0037843625 | Q22: =IF(AND(C22<>"",C21<>""),LN(C22/C21),"") -> -0.0030358712 | R22: =IF(AND(D22<>"",D21<>""),LN(D22/D21),"") -> -0.00076602017 | S22: =IF(AND(E22<>"",E21<>""),LN(E22/E21),"") -> 0.0060357216 | T22: =IF(AND(F22<>"",F21<>""),LN(F22/F21),"") -> 0.0021446707 | U22: =IF(AND(G22<>"",G21<>""),LN(G22/G21),"") | V22: =IF(AND(H22<>"",H21<>""),LN(H22/H21),"") -> 0 | W22: =IF(AND(I22<>"",I21<>""),LN(I22/I21),"") -> -0.011887948 | ... Y22: =IF(AND(K22<>"",K21<>""),LN(K22/K21),"") -> 0 | Z22: -0.001328 | AA22: =IF(AND(L22<>"",L21<>""),LN(L22/L21),"") -> 0.024414716 | AB22: =IF(AND(M22<>"",M21<>""),LN(M22/M21),"") -> 0.021046431 | AE22: 43494 | AF22: 19.13 | AG22: 37.13 | AH22: 49.8 | AI22: =IF(AND(M22<>"",L22<>""),M22-L22,"") -> 7.91 | AJ22: 2.94 | AK22: 20.585 | AL22: =IF(AND(AK22<>"",AJ22<>""),AK22-AJ22,"") -> 17.645 | AM22: 2.4 | AN22: 2.56 | AO22: 2.72 | AP22: =IF(AND(AO22<>"",AN22<>""),AO22-AN22,"") -> 0.16 | AQ22: 1.78 | AR22: 114.026 | AS22: 1308.2 | AY22: 43494 | AZ22: 0 | BA22: 0 | BB22: 0 | BE22: 43494 | BF22: Pre-COVID | BG22: 1
A23: 43495 | B23: 51.8673 | C23: 82.2937 | D23: 51.197 | E23: 56.9514 | F23: 63.2175 | H23: 3.148 | I23: 16.7606 | J23: 7.7584 | K23: 76.0701 | L23: 54.18 | M23: 61.89 | O23: 43495 | P23: =IF(AND(B23<>"",B22<>""),LN(B23/B22),"") -> 0.010847695 | Q23: =IF(AND(C23<>"",C22<>""),LN(C23/C22),"") -> 0.010496767 | R23: =IF(AND(D23<>"",D22<>""),LN(D23/D22),"") -> 0.005955547 | S23: =IF(AND(E23<>"",E22<>""),LN(E23/E22),"") -> 0.0073436636 | T23: =IF(AND(F23<>"",F22<>""),LN(F23/F22),"") -> 0.011401805 | U23: =IF(AND(G23<>"",G22<>""),LN(G23/G22),"") | V23: =IF(AND(H23<>"",H22<>""),LN(H23/H22),"") -> 0.024633847 | W23: =IF(AND(I23<>"",I22<>""),LN(I23/I22),"") -> -0.018104162 | ... Y23: =IF(AND(K23<>"",K22<>""),LN(K23/K22),"") -> 0.00021824359 | Z23: 0.015707 | AA23: =IF(AND(L23<>"",L22<>""),LN(L23/L22),"") -> 0.02070004 | AB23: =IF(AND(M23<>"",M22<>""),LN(M23/M22),"") -> 0.014812674 | AE23: 43495 | AF23: 17.66 | AG23: 35.59 | AH23: 48.32 | AI23: =IF(AND(M23<>"",L23<>""),M23-L23,"") -> 7.71 | AJ23: 3 | AK23: 20.18 | AL23: =IF(AND(AK23<>"",AJ23<>""),AK23-AJ23,"") -> 17.18 | AM23: 2.4 | AN23: 2.52 | AO23: 2.7 | AP23: =IF(AND(AO23<>"",AN23<>""),AO23-AN23,"") -> 0.18 | AQ23: 1.84 | AR23: 114.0731 | AS23: 1309.9 | AY23: 43495 | AZ23: 0 | BA23: 0 | BB23: 0 | BE23: 43495 | BF23: Pre-COVID | BG23: 1
A24: 43496 | B24: 52.5776 | C24: 83.4879 | D24: 52.7557 | E24: 56.7898 | F24: 62.7397 | H24: 3.036 | I24: 15.9273 | J24: 7.7796 | K24: 76.0701 | L24: 53.84 | M24: 62.46 | O24: 43496 | P24: =IF(AND(B24<>"",B23<>""),LN(B24/B23),"") -> 0.01360164 | Q24: =IF(AND(C24<>"",C23<>""),LN(C24/C23),"") -> 0.014407156 | R24: =IF(AND(D24<>"",D23<>""),LN(D24/D23),"") -> 0.029990887 | S24: =IF(AND(E24<>"",E23<>""),LN(E24/E23),"") -> -0.0028415404 | T24: =IF(AND(F24<>"",F23<>""),LN(F24/F23),"") -> -0.0075867404 | U24: =IF(AND(G24<>"",G23<>""),LN(G24/G23),"") | V24: =IF(AND(H24<>"",H23<>""),LN(H24/H23),"") -> -0.036226471 | W24: =IF(AND(I24<>"",I23<>""),LN(I24/I23),"") -> -0.050996276 | ... Y24: =IF(AND(K24<>"",K23<>""),LN(K24/K23),"") -> 0 | Z24: 0.008744 | AA24: =IF(AND(L24<>"",L23<>""),LN(L24/L23),"") -> -0.0062951513 | AB24: =IF(AND(M24<>"",M23<>""),LN(M24/M23),"") -> 0.0091677361 | AE24: 43496 | AF24: 16.57 | AG24: 34.97 | AH24: 49.81 | AI24: =IF(AND(M24<>"",L24<>""),M24-L24,"") -> 8.62 | AJ24: 2.82 | AK24: 19.85 | AL24: =IF(AND(AK24<>"",AJ24<>""),AK24-AJ24,"") -> 17.03 | AM24: 2.4 | AN24: 2.45 | AO24: 2.63 | AP24: =IF(AND(AO24<>"",AN24<>""),AO24-AN24,"") -> 0.18 | AQ24: 1.85 | AR24: 113.5504 | AS24: 1319.7 | AY24: 43496 | AZ24: 0 | BA24: 0 | BB24: 0 | BE24: 43496 | BF24: Pre-COVID | BG24: 1
A25: 43497 | B25: 54.4718 | C25: 86.1968 | D25: 53.5273 | E25: 57.8613 | F25: 64.0012 | H25: 2.9889 | I25: 15.7147 | J25: 7.9541 | K25: 76.0776 | L25: 55.29 | M25: 61.86 | O25: 43497 | P25: =IF(AND(B25<>"",B24<>""),LN(B25/B24),"") -> 0.035392963 | Q25: =IF(AND(C25<>"",C24<>""),LN(C25/C24),"") -> 0.031931343 | R25: =IF(AND(D25<>"",D24<>""),LN(D25/D24),"") -> 0.014519981 | S25: =IF(AND(E25<>"",E24<>""),LN(E25/E24),"") -> 0.018692035 | T25: =IF(AND(F25<>"",F24<>""),LN(F25/F24),"") -> 0.019907412 | U25: =IF(AND(G25<>"",G24<>""),LN(G25/G24),"") | V25: =IF(AND(H25<>"",H24<>""),LN(H25/H24),"") -> -0.015635433 | W25: =IF(AND(I25<>"",I24<>""),LN(I25/I24),"") -> -0.013438038 | ... Y25: =IF(AND(K25<>"",K24<>""),LN(K25/K24),"") -> 9.8588411e-05 | Z25: 0.000481 | AA25: =IF(AND(L25<>"",L24<>""),LN(L25/L24),"") -> 0.026575375 | AB25: =IF(AND(M25<>"",M24<>""),LN(M25/M24),"") -> -0.0096525846 | AE25: 43497 | AF25: 16.14 | AG25: 33.4 | AH25: 48.79 | AI25: =IF(AND(M25<>"",L25<>""),M25-L25,"") -> 6.57 | AJ25: 2.7 | AK25: 19.3 | AL25: =IF(AND(AK25<>"",AJ25<>""),AK25-AJ25,"") -> 16.6 | AM25: 2.4 | AN25: 2.52 | AO25: 2.7 | AP25: =IF(AND(AO25<>"",AN25<>""),AO25-AN25,"") -> 0.18 | AQ25: 1.88 | AR25: 113.7548 | AS25: 1316.9 | AT25: 253.319 | AU25: 102.8371 | AV25: 93.8 | AY25: 43497 | AZ25: 0 | BA25: 0 | BB25: 0 | BE25: 43497 | BF25: Pre-COVID | BG25: 1
A26: 43500 | B26: 53.6826 | C26: 87.1944 | D26: 54.5015 | E26: 57.6062 | F26: 64.393 | H26: 3.0007 | I26: 15.6722 | J26: 7.9752 | K26: 76.086 | L26: 54.57 | M26: 62.26 | O26: 43500 | P26: =IF(AND(B26<>"",B25<>""),LN(B26/B25),"") -> -0.01459421 | Q26: =IF(AND(C26<>"",C25<>""),LN(C26/C25),"") -> 0.011507055 | R26: =IF(AND(D26<>"",D25<>""),LN(D26/D25),"") -> 0.01803642 | S26: =IF(AND(E26<>"",E25<>""),LN(E26/E25),"") -> -0.0044185665 | T26: =IF(AND(F26<>"",F25<>""),LN(F26/F25),"") -> 0.0061030984 | U26: =IF(AND(G26<>"",G25<>""),LN(G26/G25),"") | V26: =IF(AND(H26<>"",H25<>""),LN(H26/H25),"") -> 0.003940168 | W26: =IF(AND(I26<>"",I25<>""),LN(I26/I25),"") -> -0.0027081379 | ... Y26: =IF(AND(K26<>"",K25<>""),LN(K26/K25),"") -> 0.00011040748 | Z26: 0.007011 | AA26: =IF(AND(L26<>"",L25<>""),LN(L26/L25),"") -> -0.013107779 | AB26: =IF(AND(M26<>"",M25<>""),LN(M26/M25),"") -> 0.0064453978 | AE26: 43500 | AF26: 15.73 | AG26: 33.7 | AH26: 48.87 | AI26: =IF(AND(M26<>"",L26<>""),M26-L26,"") -> 7.69 | AJ26: 2.57 | AK26: 19.355 | AL26: =IF(AND(AK26<>"",AJ26<>""),AK26-AJ26,"") -> 16.785 | AM26: 2.4 | AN26: 2.53 | AO26: 2.73 | AP26: =IF(AND(AO26<>"",AN26<>""),AO26-AN26,"") -> 0.2 | AQ26: 1.87 | AR26: 113.8766 | AS26: 1314.3 | AT26: 253.319 | AU26: 102.8371 | AV26: 93.8 | AY26: 43500 | AZ26: 0 | BA26: 0 | BB26: 0 | BE26: 43500 | BF26: Pre-COVID | BG26: 1
A27: 43501 | B27: 54.235 | C27: 87.0051 | D27: 53.9793 | E27: 57.232 | F27: 64.3261 | H27: 3.1422 | I27: 15.213 | J27: 7.9858 | K27: 76.086 | L27: 53.69 | M27: 61.67 | O27: 43501 | P27: =IF(AND(B27<>"",B26<>""),LN(B27/B26),"") -> 0.01023753 | Q27: =IF(AND(C27<>"",C26<>""),LN(C27/C26),"") -> -0.002173371 | R27: =IF(AND(D27<>"",D26<>""),LN(D27/D26),"") -> -0.0096275845 | S27: =IF(AND(E27<>"",E26<>""),LN(E27/E26),"") -> -0.0065170183 | T27: =IF(AND(F27<>"",F26<>""),LN(F27/F26),"") -> -0.0010394729 | U27: =IF(AND(G27<>"",G26<>""),LN(G27/G26),"") | V27: =IF(AND(H27<>"",H26<>""),LN(H27/H26),"") -> 0.046077597 | W27: =IF(AND(I27<>"",I26<>""),LN(I27/I26),"") -> -0.029738117 | ... Y27: =IF(AND(K27<>"",K26<>""),LN(K27/K26),"") -> 0 | Z27: 0.004183 | AA27: =IF(AND(L27<>"",L26<>""),LN(L27/L26),"") -> -0.016257517 | AB27: =IF(AND(M27<>"",M26<>""),LN(M27/M26),"") -> -0.009521576 | AE27: 43501 | AF27: 15.57 | AG27: 34.57 | AH27: 48.62 | AI27: =IF(AND(M27<>"",L27<>""),M27-L27,"") -> 7.98 | AJ27: 2.54 | AK27: 19.14 | AL27: =IF(AND(AK27<>"",AJ27<>""),AK27-AJ27,"") -> 16.6 | AM27: 2.4 | AN27: 2.53 | AO27: 2.71 | AP27: =IF(AND(AO27<>"",AN27<>""),AO27-AN27,"") -> 0.18 | AQ27: 1.87 | AR27: 114.0431 | AS27: 1314.2 | AT27: 253.319 | AU27: 102.8371 | AV27: 93.8 | AY27: 43501 | AZ27: 0 | BA27: 0 | BB27: 0 | BE27: 43501 | BF27: Pre-COVID | BG27: 1
A28: 43502 | B28: 53.9982 | C28: 86.5682 | D28: 53.8624 | E28: 56.6622 | F28: 62.9881 | H28: 3.0891 | I28: 14.3541 | J28: 7.9224 | K28: 76.1026 | L28: 53.94 | M28: 62.22 | O28: 43502 | P28: =IF(AND(B28<>"",B27<>""),LN(B28/B27),"") -> -0.0043757438 | Q28: =IF(AND(C28<>"",C27<>""),LN(C28/C27),"") -> -0.005034195 | R28: =IF(AND(D28<>"",D27<>""),LN(D28/D27),"") -> -0.0021679934 | S28: =IF(AND(E28<>"",E27<>""),LN(E28/E27),"") -> -0.010005861 | T28: =IF(AND(F28<>"",F27<>""),LN(F28/F27),"") -> -0.021019639 | U28: =IF(AND(G28<>"",G27<>""),LN(G28/G27),"") | V28: =IF(AND(H28<>"",H27<>""),LN(H28/H27),"") -> -0.017043405 | W28: =IF(AND(I28<>"",I27<>""),LN(I28/I27),"") -> -0.05811471 | ... Y28: =IF(AND(K28<>"",K27<>""),LN(K28/K27),"") -> 0.00021815037 | Z28: -0.001319 | AA28: =IF(AND(L28<>"",L27<>""),LN(L28/L27),"") -> 0.0046455533 | AB28: =IF(AND(M28<>"",M27<>""),LN(M28/M27),"") -> 0.0088789025 | AE28: 43502 | AF28: 15.38 | AG28: 33.02 | AH28: 47.44 | AI28: =IF(AND(M28<>"",L28<>""),M28-L28,"") -> 8.28 | AJ28: 2.58 | AK28: 18.915 | AL28: =IF(AND(AK28<>"",AJ28<>""),AK28-AJ28,"") -> 16.335 | AM28: 2.4 | AN28: 2.52 | AO28: 2.7 | AP28: =IF(AND(AO28<>"",AN28<>""),AO28-AN28,"") -> 0.18 | AQ28: 1.86 | AR28: 114.2305 | AS28: 1309.5 | AT28: 253.319 | AU28: 102.8371 | AV28: 93.8 | AY28: 43502 | AZ28: 0 | BA28: 0 | BB28: 0 | BE28: 43502 | BF28: Pre-COVID | BG28: 1
A29: 43503 | B29: 53.5821 | C29: 86.0949 | D29: 52.592 | E29: 55.208 | F29: 62.8735 | H29: 2.9594 | I29: 13.6313 | J29: 7.7793 | K29: 76.1026 | L29: 52.68 | M29: 61.01 | O29: 43503 | P29: =IF(AND(B29<>"",B28<>""),LN(B29/B28),"") -> -0.0077356556 | Q29: =IF(AND(C29<>"",C28<>""),LN(C29/C28),"") -> -0.0054823664 | R29: =IF(AND(D29<>"",D28<>""),LN(D29/D28),"") -> -0.023868629 | S29: =IF(AND(E29<>"",E28<>""),LN(E29/E28),"") -> -0.025999451 | T29: =IF(AND(F29<>"",F28<>""),LN(F29/F28),"") -> -0.0018210484 | U29: =IF(AND(G29<>"",G28<>""),LN(G29/G28),"") | V29: =IF(AND(H29<>"",H28<>""),LN(H29/H28),"") -> -0.042893241 | W29: =IF(AND(I29<>"",I28<>""),LN(I29/I28),"") -> -0.051666997 | ... Y29: =IF(AND(K29<>"",K28<>""),LN(K29/K28),"") -> 0 | Z29: -0.009578 | AA29: =IF(AND(L29<>"",L28<>""),LN(L29/L28),"") -> -0.023636441 | AB29: =IF(AND(M29<>"",M28<>""),LN(M29/M28),"") -> -0.019638706 | AE29: 43503 | AF29: 16.37 | AG29: 34.34 | AH29: 48.97 | AI29: =IF(AND(M29<>"",L29<>""),M29-L29,"") -> 8.33 | AJ29: 2.62 | AK29: 18.91 | AL29: =IF(AND(AK29<>"",AJ29<>""),AK29-AJ29,"") -> 16.29 | AM29: 2.4 | AN29: 2.48 | AO29: 2.65 | AP29: =IF(AND(AO29<>"",AN29<>""),AO29-AN29,"") -> 0.17 | AQ29: 1.84 | AR29: 114.4339 | AS29: 1309.4 | AT29: 253.319 | AU29: 102.8371 | AV29: 93.8 | AY29: 43503 | AZ29: 0 | BA29: 0 | BB29: 0 | BE29: 43503 | BF29: Pre-COVID | BG29: 1
A30: 43504 | B30: 53.6692 | C30: 85.6215 | D30: 51.8757 | E30: 55.2421 | F30: 62.6823 | H30: 2.8887 | I30: 13.2572 | J30: 7.7523 | K30: 76.1192 | L30: 52.75 | M30: 61.37 | O30: 43504 | P30: =IF(AND(B30<>"",B29<>""),LN(B30/B29),"") -> 0.0016242231 | Q30: =IF(AND(C30<>"",C29<>""),LN(C30/C29),"") -> -0.0055137564 | R30: =IF(AND(D30<>"",D29<>""),LN(D30/D29),"") -> -0.013713544 | S30: =IF(AND(E30<>"",E29<>""),LN(E30/E29),"") -> 0.00061747343 | T30: =IF(AND(F30<>"",F29<>""),LN(F30/F29),"") -> -0.0030456601 | U30: =IF(AND(G30<>"",G29<>""),LN(G30/G29),"") | V30: =IF(AND(H30<>"",H29<>""),LN(H30/H29),"") -> -0.024179971 | W30: =IF(AND(I30<>"",I29<>""),LN(I30/I29),"") -> -0.027827818 | ... Y30: =IF(AND(K30<>"",K29<>""),LN(K30/K29),"") -> 0.0002181028 | Z30: 0.001221 | AA30: =IF(AND(L30<>"",L29<>""),LN(L30/L29),"") -> 0.0013278955 | AB30: =IF(AND(M30<>"",M29<>""),LN(M30/M29),"") -> 0.0058833312 | AE30: 43504 | AF30: 15.72 | AG30: 32.56 | AH30: 49.63 | AI30: =IF(AND(M30<>"",L30<>""),M30-L30,"") -> 8.62 | AJ30: 2.66 | AK30: 18.265 | AL30: =IF(AND(AK30<>"",AJ30<>""),AK30-AJ30,"") -> 15.605 | AM30: 2.4 | AN30: 2.45 | AO30: 2.63 | AP30: =IF(AND(AO30<>"",AN30<>""),AO30-AN30,"") -> 0.18 | AQ30: 1.82 | AR30: 114.5003 | AS30: 1313.7 | AT30: 253.319 | AU30: 102.8371 | AV30: 93.8 | AY30: 43504 | AZ30: 0 | BA30: 0 | BB30: 0 | BE30: 43504 | BF30: Pre-COVID | BG30: 1
A31: 43507 | B31: 53.7562 | C31: 85.1628 | D31: 52.2515 | E31: 55.14 | F31: 62.4434 | H31: 2.9653 | I31: 13.7929 | J31: 7.6929 | K31: 76.1109 | L31: 52.43 | M31: 61.3 | O31: 43507 | P31: =IF(AND(B31<>"",B30<>""),LN(B31/B30),"") -> 0.001619729 | Q31: =IF(AND(C31<>"",C30<>""),LN(C31/C30),"") -> -0.0053717011 | R31: =IF(AND(D31<>"",D30<>""),LN(D31/D30),"") -> 0.0072181261 | S31: =IF(AND(E31<>"",E30<>""),LN(E31/E30),"") -> -0.0018499382 | T31: =IF(AND(F31<>"",F30<>""),LN(F31/F30),"") -> -0.0038185647 | U31: =IF(AND(G31<>"",G30<>""),LN(G31/G30),"") | V31: =IF(AND(H31<>"",H30<>""),LN(H31/H30),"") -> 0.026171634 | W31: =IF(AND(I31<>"",I30<>""),LN(I31/I30),"") -> 0.039613166 | ... Y31: =IF(AND(K31<>"",K30<>""),LN(K31/K30),"") -> -0.00010904545 | Z31: 0.000554 | AA31: =IF(AND(L31<>"",L30<>""),LN(L31/L30),"") -> -0.0060848258 | AB31: =IF(AND(M31<>"",M30<>""),LN(M31/M30),"") -> -0.0011412735 | AE31: 43507 | AF31: 15.97 | AG31: 33.34 | AH31: 48.32 | AI31: =IF(AND(M31<>"",L31<>""),M31-L31,"") -> 8.87 | AJ31: 2.76 | AK31: 18.055 | AL31: =IF(AND(AK31<>"",AJ31<>""),AK31-AJ31,"") -> 15.295 | AM31: 2.4 | AN31: 2.48 | AO31: 2.65 | AP31: =IF(AND(AO31<>"",AN31<>""),AO31-AN31,"") -> 0.17 | AQ31: 1.82 | AR31: 115.031 | AS31: 1307 | AT31: 253.319 | AU31: 102.8371 | AV31: 93.8 | AY31: 43507 | AZ31: 0 | BA31: 0 | BB31: 0 | BE31: 43507 | BF31: Pre-COVID | BG31: 1
A32: 43508 | B32: 54.6993 | C32: 86.4517 | D32: 52.8073 | E32: 55.9139 | F32: 62.9021 | H32: 3.2365 | I32: 14.4562 | J32: 7.8495 | K32: 76.1275 | L32: 53.14 | M32: 62.58 | O32: 43508 | P32: =IF(AND(B32<>"",B31<>""),LN(B32/B31),"") -> 0.017391903 | Q32: =IF(AND(C32<>"",C31<>""),LN(C32/C31),"") -> 0.015021158 | R32: =IF(AND(D32<>"",D31<>""),LN(D32/D31),"") -> 0.01058084 | S32: =IF(AND(E32<>"",E31<>""),LN(E32/E31),"") -> 0.013937602 | T32: =IF(AND(F32<>"",F31<>""),LN(F32/F31),"") -> 0.007319003 | U32: =IF(AND(G32<>"",G31<>""),LN(G32/G31),"") | V32: =IF(AND(H32<>"",H31<>""),LN(H32/H31),"") -> 0.087514291 | W32: =IF(AND(I32<>"",I31<>""),LN(I32/I31),"") -> 0.046969421 | ... Y32: =IF(AND(K32<>"",K31<>""),LN(K32/K31),"") -> 0.00021807901 | Z32: 0.012778 | AA32: =IF(AND(L32<>"",L31<>""),LN(L32/L31),"") -> 0.013450994 | AB32: =IF(AND(M32<>"",M31<>""),LN(M32/M31),"") -> 0.020665895 | AE32: 43508 | AF32: 15.43 | AG32: 32.69 | AH32: 49.02 | AI32: =IF(AND(M32<>"",L32<>""),M32-L32,"") -> 9.44 | AJ32: 2.71 | AK32: 17.785 | AL32: =IF(AND(AK32<>"",AJ32<>""),AK32-AJ32,"") -> 15.075 | AM32: 2.4 | AN32: 2.5 | AO32: 2.68 | AP32: =IF(AND(AO32<>"",AN32<>""),AO32-AN32,"") -> 0.18 | AQ32: 1.83 | AR32: 114.7297 | AS32: 1309.2 | AT32: 253.319 | AU32: 102.8371 | AV32: 93.8 | AY32: 43508 | AZ32: 0 | BA32: 0 | BB32: 0 | BE32: 43508 | BF32: Pre-COVID | BG32: 1
A33: 43509 | B33: 55.316 | C33: 87.0707 | D33: 53.0657 | E33: 55.9989 | F33: 62.9308 | H33: 3.2365 | I33: 15.1705 | J33: 8.0006 | K33: 76.1275 | L33: 53.84 | M33: 63.27 | O33: 43509 | P33: =IF(AND(B33<>"",B32<>""),LN(B33/B32),"") -> 0.011211285 | Q33: =IF(AND(C33<>"",C32<>""),LN(C33/C32),"") -> 0.0071345558 | R33: =IF(AND(D33<>"",D32<>""),LN(D33/D32),"") -> 0.0048813298 | S33: =IF(AND(E33<>"",E32<>""),LN(E33/E32),"") -> 0.0015190401 | T33: =IF(AND(F33<>"",F32<>""),LN(F33/F32),"") -> 0.00045616052 | U33: =IF(AND(G33<>"",G32<>""),LN(G33/G32),"") | V33: =IF(AND(H33<>"",H32<>""),LN(H33/H32),"") -> 0 | W33: =IF(AND(I33<>"",I32<>""),LN(I33/I32),"") -> 0.048229364 | ... Y33: =IF(AND(K33<>"",K32<>""),LN(K33/K32),"") -> 0 | Z33: 0.003241 | AA33: =IF(AND(L33<>"",L32<>""),LN(L33/L32),"") -> 0.013086745 | AB33: =IF(AND(M33<>"",M32<>""),LN(M33/M32),"") -> 0.010965545 | AE33: 43509 | AF33: 15.65 | AG33: 32.26 | AH33: 48.17 | AI33: =IF(AND(M33<>"",L33<>""),M33-L33,"") -> 9.43 | AJ33: 2.61 | AK33: 18.02 | AL33: =IF(AND(AK33<>"",AJ33<>""),AK33-AJ33,"") -> 15.41 | AM33: 2.4 | AN33: 2.53 | AO33: 2.71 | AP33: =IF(AND(AO33<>"",AN33<>""),AO33-AN33,"") -> 0.18 | AQ33: 1.86 | AR33: 114.9407 | AS33: 1310.8 | AT33: 253.319 | AU33: 102.8371 | AV33: 93.8 | AY33: 43509 | AZ33: 0 | BA33: 0 | BB33: 0 | BE33: 43509 | BF33: Pre-COVID | BG33: 1
A34: 43510 | B34: 55.3305 | C34: 86.9088 | D34: 54.0991 | E34: 56.6112 | F34: 63.0742 | H34: 3.3544 | I34: 16.4885 | J34: 8.1032 | K34: 76.1442 | L34: 54.4 | M34: 64 | O34: 43510 | P34: =IF(AND(B34<>"",B33<>""),LN(B34/B33),"") -> 0.00026209596 | Q34: =IF(AND(C34<>"",C33<>""),LN(C34/C33),"") -> -0.0018611393 | R34: =IF(AND(D34<>"",D33<>""),LN(D34/D33),"") -> 0.019286781 | S34: =IF(AND(E34<>"",E33<>""),LN(E34/E33),"") -> 0.010874798 | T34: =IF(AND(F34<>"",F33<>""),LN(F34/F33),"") -> 0.0022761011 | U34: =IF(AND(G34<>"",G33<>""),LN(G34/G33),"") | V34: =IF(AND(H34<>"",H33<>""),LN(H34/H33),"") -> 0.035780418 | W34: =IF(AND(I34<>"",I33<>""),LN(I34/I33),"") -> 0.083310416 | ... Y34: =IF(AND(K34<>"",K33<>""),LN(K34/K33),"") -> 0.00021934476 | Z34: -0.002221 | AA34: =IF(AND(L34<>"",L33<>""),LN(L34/L33),"") -> 0.010347469 | AB34: =IF(AND(M34<>"",M33<>""),LN(M34/M33),"") -> 0.0114718 | AE34: 43510 | AF34: 16.22 | AG34: 32.1 | AH34: 47.19 | AI34: =IF(AND(M34<>"",L34<>""),M34-L34,"") -> 9.6 | AJ34: 2.61 | AK34: 17.755 | AL34: =IF(AND(AK34<>"",AJ34<>""),AK34-AJ34,"") -> 15.145 | AM34: 2.4 | AN34: 2.5 | AO34: 2.66 | AP34: =IF(AND(AO34<>"",AN34<>""),AO34-AN34,"") -> 0.16 | AQ34: 1.85 | AR34: 115.1007 | AS34: 1309.8 | AT34: 253.319 | AU34: 102.8371 | AV34: 93.8 | AY34: 43510 | AZ34: 0 | BA34: 0 | BB34: 0 | BE34: 43510 | BF34: Pre-COVID | BG34: 1
A35: 43511 | B35: 56.3751 | C35: 87.7841 | D35: 54.9447 | E35: 57.1385 | F35: 63.2844 | H35: 3.4487 | I35: 16.8117 | J35: 8.1248 | K35: 76.1442 | L35: 55.58 | M35: 65.65 | O35: 43511 | P35: =IF(AND(B35<>"",B34<>""),LN(B35/B34),"") -> 0.018703278 | Q35: =IF(AND(C35<>"",C34<>""),LN(C35/C34),"") -> 0.010021098 | R35: =IF(AND(D35<>"",D34<>""),LN(D35/D34),"") -> 0.015509675 | S35: =IF(AND(E35<>"",E34<>""),LN(E35/E34),"") -> 0.0092712997 | T35: =IF(AND(F35<>"",F34<>""),LN(F35/F34),"") -> 0.0033270421 | U35: =IF(AND(G35<>"",G34<>""),LN(G35/G34),"") | V35: =IF(AND(H35<>"",H34<>""),LN(H35/H34),"") -> 0.027724432 | W35: =IF(AND(I35<>"",I34<>""),LN(I35/I34),"") -> 0.019411904 | ... Y35: =IF(AND(K35<>"",K34<>""),LN(K35/K34),"") -> 0 | Z35: 0.010839 | AA35: =IF(AND(L35<>"",L34<>""),LN(L35/L34),"") -> 0.02145927 | AB35: =IF(AND(M35<>"",M34<>""),LN(M35/M34),"") -> 0.025454517 | AE35: 43511 | AF35: 14.91 | AG35: 29.46 | AH35: 45.73 | AI35: =IF(AND(M35<>"",L35<>""),M35-L35,"") -> 10.07 | AJ35: 2.59 | AK35: 18.1 | AL35: =IF(AND(AK35<>"",AJ35<>""),AK35-AJ35,"") -> 15.51 | AM35: 2.4 | AN35: 2.52 | AO35: 2.66 | AP35: =IF(AND(AO35<>"",AN35<>""),AO35-AN35,"") -> 0.14 | AQ35: 1.86 | AR35: 114.9923 | AS35: 1318.1 | AT35: 253.319 | AU35: 102.8371 | AV35: 93.8 | AY35: 43511 | AZ35: 0 | BA35: 0 | BB35: 0 | BE35: 43511 | BF35: Pre-COVID | BG35: 1
A36: 43515 | B36: 56.7524 | C36: 87.7547 | D36: 54.4044 | E36: 57.5126 | F36: 63.9438 | H36: 3.4605 | I36: 16.9647 | J36: 8.4325 | K36: 76.1608 | L36: 56.12 | M36: 65.86 | O36: 43515 | P36: =IF(AND(B36<>"",B35<>""),LN(B36/B35),"") -> 0.0066703746 | Q36: =IF(AND(C36<>"",C35<>""),LN(C36/C35),"") -> -0.00033496868 | R36: =IF(AND(D36<>"",D35<>""),LN(D36/D35),"") -> -0.0098821919 | S36: =IF(AND(E36<>"",E35<>""),LN(E36/E35),"") -> 0.0065259091 | T36: =IF(AND(F36<>"",F35<>""),LN(F36/F35),"") -> 0.010365719 | U36: =IF(AND(G36<>"",G35<>""),LN(G36/G35),"") | V36: =IF(AND(H36<>"",H35<>""),LN(H36/H35),"") -> 0.0034157389 | W36: =IF(AND(I36<>"",I35<>""),LN(I36/I35),"") -> 0.009059642 | ... Y36: =IF(AND(K36<>"",K35<>""),LN(K36/K35),"") -> 0.00021798365 | Z36: 0.001729 | AA36: =IF(AND(L36<>"",L35<>""),LN(L36/L35),"") -> 0.0096688309 | AB36: =IF(AND(M36<>"",M35<>""),LN(M36/M35),"") -> 0.0031936762 | AE36: 43515 | AF36: 14.88 | AG36: 31 | AH36: 45.06 | AI36: =IF(AND(M36<>"",L36<>""),M36-L36,"") -> 9.74 | AJ36: 2.69 | AK36: 17.705 | AL36: =IF(AND(AK36<>"",AJ36<>""),AK36-AJ36,"") -> 15.015 | AM36: 2.4 | AN36: 2.5 | AO36: 2.65 | AP36: =IF(AND(AO36<>"",AN36<>""),AO36-AN36,"") -> 0.15 | AQ36: 1.87 | AR36: 114.57 | AS36: 1340.1 | AT36: 253.319 | AU36: 102.8371 | AV36: 93.8 | AY36: 43515 | AZ36: 0 | BA36: 0 | BB36: 0 | BE36: 43515 | BF36: Pre-COVID | BG36: 1
A37: 43516 | B37: 56.97 | C37: 88.4681 | D37: 55.3126 | E37: 58.0399 | F37: 63.0359 | H37: 3.3721 | I37: 16.7266 | J37: 8.3677 | K37: 76.1608 | L37: 56.9 | M37: 66.82 | O37: 43516 | P37: =IF(AND(B37<>"",B36<>""),LN(B37/B36),"") -> 0.0038268673 | Q37: =IF(AND(C37<>"",C36<>""),LN(C37/C36),"") -> 0.0080966129 | R37: =IF(AND(D37<>"",D36<>""),LN(D37/D36),"") -> 0.016555698 | S37: =IF(AND(E37<>"",E36<>""),LN(E37/E36),"") -> 0.0091266508 | T37: =IF(AND(F37<>"",F36<>""),LN(F37/F36),"") -> -0.014300167 | U37: =IF(AND(G37<>"",G36<>""),LN(G37/G36),"") | V37: =IF(AND(H37<>"",H36<>""),LN(H37/H36),"") -> -0.025877392 | W37: =IF(AND(I37<>"",I36<>""),LN(I37/I36),"") -> -0.014134448 | ... Y37: =IF(AND(K37<>"",K36<>""),LN(K37/K36),"") -> 0 | Z37: 0.002014 | AA37: =IF(AND(L37<>"",L36<>""),LN(L37/L36),"") -> 0.013803086 | AB37: =IF(AND(M37<>"",M36<>""),LN(M37/M36),"") -> 0.01447116 | AE37: 43516 | AF37: 14.02 | AG37: 30.76 | AH37: 44.54 | AI37: =IF(AND(M37<>"",L37<>""),M37-L37,"") -> 9.92 | AJ37: 2.69 | AK37: 18.145 | AL37: =IF(AND(AK37<>"",AJ37<>""),AK37-AJ37,"") -> 15.455 | AM37: 2.4 | AN37: 2.5 | AO37: 2.65 | AP37: =IF(AND(AO37<>"",AN37<>""),AO37-AN37,"") -> 0.15 | AQ37: 1.89 | AS37: 1343.3 | AT37: 253.319 | AU37: 102.8371 | AV37: 93.8 | AY37: 43516 | AZ37: 0 | BA37: 0 | BB37: 0 | BE37: 43516 | BF37: Pre-COVID | BG37: 1
A38: 43517 | B38: 56.4549 | C38: 87.6296 | D38: 54.9916 | E38: 56.6367 | F38: 62.4625 | H38: 3.3839 | I38: 16.6331 | J38: 8.3893 | K38: 76.1691 | L38: 56.95 | M38: 66.91 | O38: 43517 | P38: =IF(AND(B38<>"",B37<>""),LN(B38/B37),"") -> -0.0090827242 | Q38: =IF(AND(C38<>"",C37<>""),LN(C38/C37),"") -> -0.0095231946 | R38: =IF(AND(D38<>"",D37<>""),LN(D38/D37),"") -> -0.0058202844 | S38: =IF(AND(E38<>"",E37<>""),LN(E38/E37),"") -> -0.02447352 | T38: =IF(AND(F38<>"",F37<>""),LN(F38/F37),"") -> -0.0091380287 | U38: =IF(AND(G38<>"",G37<>""),LN(G38/G37),"") | V38: =IF(AND(H38<>"",H37<>""),LN(H38/H37),"") -> 0.0034931948 | W38: =IF(AND(I38<>"",I37<>""),LN(I38/I37),"") -> -0.0056055807 | ... Y38: =IF(AND(K38<>"",K37<>""),LN(K38/K37),"") -> 0.00010897401 | Z38: -0.003562 | AA38: =IF(AND(L38<>"",L37<>""),LN(L38/L37),"") -> 0.00087834876 | AB38: =IF(AND(M38<>"",M37<>""),LN(M38/M37),"") -> 0.0013459959 | AE38: 43517 | AF38: 14.46 | AG38: 30.16 | AH38: 46.55 | AI38: =IF(AND(M38<>"",L38<>""),M38-L38,"") -> 9.96 | AJ38: 2.73 | AK38: 17.52 | AL38: =IF(AND(AK38<>"",AJ38<>""),AK38-AJ38,"") -> 14.79 | AM38: 2.4 | AN38: 2.53 | AO38: 2.69 | AP38: =IF(AND(AO38<>"",AN38<>""),AO38-AN38,"") -> 0.16 | AQ38: 1.91 | AR38: 114.5091 | AS38: 1323.5 | AT38: 253.319 | AU38: 102.8371 | AV38: 93.8 | AY38: 43517 | AZ38: 0 | BA38: 0 | BB38: 0 | BE38: 43517 | BF38: Pre-COVID | BG38: 1
A39: 43518 | B39: 56.8902 | C39: 87.8135 | D39: 54.7803 | E39: 56.067 | F39: 62.3096 | H39: 3.5725 | I39: 16.5225 | J39: 8.2976 | K39: 76.1858 | L39: 57.01 | M39: 66.91 | O39: 43518 | P39: =IF(AND(B39<>"",B38<>""),LN(B39/B38),"") -> 0.007681005 | Q39: =IF(AND(C39<>"",C38<>""),LN(C39/C38),"") -> 0.002096407 | R39: =IF(AND(D39<>"",D38<>""),LN(D39/D38),"") -> -0.003849806 | S39: =IF(AND(E39<>"",E38<>""),LN(E39/E38),"") -> -0.010109781 | T39: =IF(AND(F39<>"",F38<>""),LN(F39/F38),"") -> -0.0024508697 | U39: =IF(AND(G39<>"",G38<>""),LN(G39/G38),"") | V39: =IF(AND(H39<>"",H38<>""),LN(H39/H38),"") -> 0.05423674 | W39: =IF(AND(I39<>"",I38<>""),LN(I39/I38),"") -> -0.0066715976 | ... Y39: =IF(AND(K39<>"",K38<>""),LN(K39/K38),"") -> 0.00021922498 | Z39: 0.006181 | AA39: =IF(AND(L39<>"",L38<>""),LN(L39/L38),"") -> 0.0010530012 | AB39: =IF(AND(M39<>"",M38<>""),LN(M39/M38),"") -> 0 | AE39: 43518 | AF39: 13.51 | AG39: 29.85 | AH39: 47.22 | AI39: =IF(AND(M39<>"",L39<>""),M39-L39,"") -> 9.9 | AJ39: 2.74 | AK39: 17.23 | AL39: =IF(AND(AK39<>"",AJ39<>""),AK39-AJ39,"") -> 14.49 | AM39: 2.4 | AN39: 2.48 | AO39: 2.65 | AP39: =IF(AND(AO39<>"",AN39<>""),AO39-AN39,"") -> 0.17 | AQ39: 1.91 | AR39: 114.2716 | AS39: 1329.2 | AT39: 253.319 | AU39: 102.8371 | AV39: 93.8 | AY39: 43518 | AZ39: 0 | BA39: 0 | BB39: 0 | BE39: 43518 | BF39: Pre-COVID | BG39: 1
A40: 43521 | B40: 56.9482 | C40: 87.9827 | D40: 54.2166 | E40: 56.3221 | F40: 61.7649 | H40: 3.431 | I40: 16.5821 | J40: 8.2976 | K40: 76.1775 | L40: 55.32 | M40: 64.02 | O40: 43521 | P40: =IF(AND(B40<>"",B39<>""),LN(B40/B39),"") -> 0.0010189884 | Q40: =IF(AND(C40<>"",C39<>""),LN(C40/C39),"") -> 0.0019249569 | R40: =IF(AND(D40<>"",D39<>""),LN(D40/D39),"") -> -0.010343506 | S40: =IF(AND(E40<>"",E39<>""),LN(E40/E39),"") -> 0.0045395939 | T40: =IF(AND(F40<>"",F39<>""),LN(F40/F39),"") -> -0.0087802651 | U40: =IF(AND(G40<>"",G39<>""),LN(G40/G39),"") | V40: =IF(AND(H40<>"",H39<>""),LN(H40/H39),"") -> -0.040413867 | W40: =IF(AND(I40<>"",I39<>""),LN(I40/I39),"") -> 0.0036007119 | ... Y40: =IF(AND(K40<>"",K39<>""),LN(K40/K39),"") -> -0.00010895012 | Z40: 0.001361 | AA40: =IF(AND(L40<>"",L39<>""),LN(L40/L39),"") -> -0.030092184 | AB40: =IF(AND(M40<>"",M39<>""),LN(M40/M39),"") -> -0.044152898 | AE40: 43521 | AF40: 14.85 | AG40: 32.69 | AH40: 46.16 | AI40: =IF(AND(M40<>"",L40<>""),M40-L40,"") -> 8.7 | AJ40: 2.84 | AK40: 16.945 | AL40: =IF(AND(AK40<>"",AJ40<>""),AK40-AJ40,"") -> 14.105 | AM40: 2.4 | AN40: 2.51 | AO40: 2.67 | AP40: =IF(AND(AO40<>"",AN40<>""),AO40-AN40,"") -> 0.16 | AQ40: 1.92 | AR40: 114.1457 | AS40: 1325.9 | AT40: 253.319 | AU40: 102.8371 | AV40: 93.8 | AY40: 43521 | AZ40: 0 | BA40: 0 | BB40: 0 | BE40: 43521 | BF40: Pre-COVID | BG40: 1
...

Sheet 02_Regime
A1: MACRO REGIME DASHBOARD
A2: DEF: Regime Classification
A3: Date | B3: Regime ID | C3: Regime Name | D3: VIX | E3: OVX | F3: 2s10s | G3: WTI
A4: 43467 | B4: 0 | C4: Transition | D4: 23.22 | E4: 54.72 | F4: 0.16 | G4: 46.31
A5: 43468 | B5: 0 | C5: Transition | D5: 25.45 | E5: 53.57 | F5: 0.17 | G5: 46.92
A6: 43469 | B6: 0 | C6: Transition | D6: 21.38 | E6: 51.52 | F6: 0.17 | G6: 47.76
A7: 43472 | B7: 0 | C7: Transition | D7: 21.4 | E7: 50.42 | F7: 0.17 | G7: 48.27
A8: 43473 | B8: 0 | C8: Transition | D8: 20.47 | E8: 46.08 | F8: 0.15 | G8: 49.58
A9: 43474 | B9: 0 | C9: Transition | D9: 19.98 | E9: 44.36 | F9: 0.18 | G9: 52.19
A10: 43475 | B10: 0 | C10: Transition | D10: 19.5 | E10: 42.99 | F10: 0.18 | G10: 52.42
A11: 43476 | B11: 0 | C11: Transition | D11: 18.19 | E11: 40.99 | F11: 0.16 | G11: 51.44
A12: 43479 | B12: 0 | C12: Transition | D12: 19.07 | E12: 40.81 | F12: 0.18 | G12: 50.31
A13: 43480 | B13: 0 | C13: Transition | D13: 18.6 | E13: 39.75 | F13: 0.19 | G13: 51.8
A14: 43481 | B14: 0 | C14: Transition | D14: 19.04 | E14: 38.77 | F14: 0.18 | G14: 52.08
A15: 43482 | B15: 0 | C15: Transition | D15: 18.06 | E15: 37.03 | F15: 0.19 | G15: 51.83
... A130: 43649 | B130: 0 | C130: Transition | D130: 12.57 | E130: 36.72 | F130: 0.19 | G130: 57.06
A131: 43651 | B131: 0 | C131: Transition | D131: 13.28 | E131: 34.7 | F131: 0.17
A132: 43654 | B132: 0 | C132: Transition | D132: 13.96 | E132: 34 | F132: 0.17 | G132: 57.35
A133: 43655 | B133: 0 | C133: Transition | D133: 14.09 | E133: 30.3 | F133: 0.15 | G133: 57.57
A134: 43656 | B134: 0 | C134: Transition | D134: 13.03 | E134: 30.76 | F134: 0.25 | G134: 60.28
A135: 43657 | B135: 0 | C135: Transition | D135: 12.93 | E135: 29.86 | F135: 0.28 | G135: 59.93
A136: 43658 | B136: 0 | C136: Transition | D136: 12.39 | E136: 30.39 | F136: 0.28 | G136: 59.99
A137: 43661 | B137: 0 | C137: Transition | D137: 12.68 | E137: 30.83 | F137: 0.26 | G137: 59.3
A138: 43662 | B138: 0 | C138: Transition | D138: 12.86 | E138: 32.06 | F138: 0.26 | G138: 57.44
A139: 43663 | B139: 0 | C139: Transition | D139: 13.97 | E139: 34.94 | F139: 0.23 | G139: 56.5
A140: 43664 | B140: 0 | C140: Transition | D140: 13.53 | E140: 33.07 | F140: 0.27 | G140: 55.08
A141: 43665 | B141: 0 | C141: Transition | D141: 14.45 | E141: 34.84 | F141: 0.25 | G141: 55.42
A142: 43668 | B142: 0 | C142: Transition | D142: 13.53 | E142: 33.63 | F142: 0.25 | G142: 55.87
A143: 43669 | B143: 0 | C143: Transition | D143: 12.61 | E143: 32.25 | F143: 0.25 | G143: 56.58
... A200: 43749 | B200: 0 | C200: Transition | D200: 15.58 | E200: 39.65 | F200: 0.13 | G200: 54.76
A201: 43752 | B201: 0 | C201: Transition | D201: 14.57 | E201: 40.21 | G201: 53.57
A202: 43753 | B202: 0 | C202: Transition | D202: 13.54 | E202: 39.47 | F202: 0.16 | G202: 52.81
A203: 43754 | B203: 0 | C203: Transition | D203: 13.68 | E203: 39.47 | F203: 0.17 | G203: 53.42
A204: 43755 | B204: 0 | C204: Transition | D204: 13.79 | E204: 37.71 | F204: 0.16 | G204: 53.89
A205: 43756 | B205: 0 | C205: Transition | D205: 14.25 | E205: 36.43 | F205: 0.18 | G205: 53.75
A206: 43759 | B206: 0 | C206: Transition | D206: 14 | E206: 36.66 | F206: 0.18 | G206: 53.28
A207: 43760 | B207: 0 | C207: Transition | D207: 14.46 | E207: 35.52 | F207: 0.18 | G207: 54.21
A208: 43761 | B208: 0 | C208: Transition | D208: 14.01 | E208: 35.66 | F208: 0.19 | G208: 55.9
A209: 43762 | B209: 0 | C209: Transition | D209: 13.71 | E209: 35.95 | F209: 0.19 | G209: 56.11
A210: 43763 | B210: 0 | C210: Transition | D210: 12.65 | E210: 34.64 | F210: 0.17 | G210: 56.52
...

Sheet 03_Profiles
A1: COMPANY PROFILES & FUNDAMENTAL SNAPSHOT
A3: XOM — Exxon Mobil
A4: Company Name | B4: Exxon Mobil
A5: Subsector | B5: Integrated Major
A6: Market Cap | B6: 460000000000
A7: Enterprise Value | B7: 490000000000
A8: FY2025 Revenue | B8: 340000000000
A9: FY2025 EBITDA | B9: 55000000000
A10: FY2025 Net Income | B10: 33000000000
A11: FY2025 EPS | B11: 8
A12: P/E (TTM) | B12: 14
A13: EV/EBITDA | B13: 9
A14: Dividend Yield | B14: 0.035
A15: Net Debt / EBITDA | B15: 0.5
A16: FCF Yield | B16: 0.08
A17: Production | B17: 3.7M boe/d
A18: Current Price (latest) | B18: ='01_Data'!B1826 -> 160.69
A19: Oil Beta (from Tab 6) | B19: (see Tab 06_Regression)
A20: Geopolitical Sensitivity | B20: (see Tab 06_Regression)
A22: CVX — Chevron
A23: Company Name | B23: Chevron
A24: Subsector | B24: Integrated Major
A25: Market Cap | B25: 270000000000
A26: Enterprise Value | B26: 290000000000
A27: FY2025 Revenue | B27: 195000000000
A28: FY2025 EBITDA | B28: 45000000000
A29: FY2025 Net Income | B29: 18000000000
A30: FY2025 EPS | B30: 9.5
A31: P/E (TTM) | B31: 15
A32: EV/EBITDA | B32: 6.5
A33: Dividend Yield | B33: 0.043
A34: Net Debt / EBITDA | B34: 0.8
A35: FCF Yield | B35: 0.07
A36: Production | B36: 3.7M boe/d
A37: Current Price (latest) | B37: ='01_Data'!C1826 -> 198.97
A38: Oil Beta (from Tab 6) | B38: (see Tab 06_Regression)
A39: Geopolitical Sensitivity | B39: (see Tab 06_Regression)
A41: COP — ConocoPhillips
A42: Company Name | B42: ConocoPhillips
A43: Subsector | B43: Pure E&P
...

Sheet 04_Performance
A1: HISTORICAL PERFORMANCE ANALYTICS
A3: SECTION A — FULL-PERIOD DESCRIPTIVE STATISTICS
A4: DEF: Descriptive Statistics
A5: Annualized mean = AVERAGE(daily log returns) * 252. Annualized vol = STDEV.S * SQRT(252). Sharpe = (AnnMean - Rf) / AnnVol.
A6: Ticker | B6: N | C6: Ann Mean Ret | D6: Ann Volatility | E6: Skewness | F6: Excess Kurtosis | G6: Max Daily Ret | H6: Min Daily Ret | I6: Max Drawdown | J6: Sharpe Ratio | K6: Sortino Ratio | L6: Calmar Ratio
A7: XOM | B7: 1822 | C7: =AVERAGE('01_Data'!P4:P1826)*252 -> 0.16146506 | D7: =_xlfn.STDEV.S('01_Data'!P4:P1826)*SQRT(252) -> 0.31112703 | E7: =SKEW('01_Data'!P4:P1826) -> -0.22353143 | F7: =KURT('01_Data'!P4:P1826) -> 5.3132667 | G7: =MAX('01_Data'!P4:P1826) -> 0.11943962 | H7: =MIN('01_Data'!P4:P1826) -> -0.1303929 | I7: -0.60347368 | J7: =(C7-0.0319)/D7 -> 0.41643783 | K7: 0.59019745 | L7: 0.26755922
A8: CVX | B8: 1822 | C8: =AVERAGE('01_Data'!Q4:Q1826)*252 -> 0.12497697 | D8: =_xlfn.STDEV.S('01_Data'!Q4:Q1826)*SQRT(252) -> 0.3224034 | E8: =SKEW('01_Data'!Q4:Q1826) -> -1.1294611 | F8: =KURT('01_Data'!Q4:Q1826) -> 26.352214 | G8: =MAX('01_Data'!Q4:Q1826) -> 0.20490391 | H8: =MIN('01_Data'!Q4:Q1826) -> -0.25006283 | I8: -0.55773924 | J8: =(C8-0.0319)/D8 -> 0.28869722 | K8: 0.39243204 | L8: 0.22407765
A9: COP | B9: 1822 | C9: =AVERAGE('01_Data'!R4:R1826)*252 -> 0.13438777 | D9: =_xlfn.STDEV.S('01_Data'!R4:R1826)*SQRT(252) -> 0.40685414 | E9: =SKEW('01_Data'!R4:R1826) -> -0.65836002 | F9: =KURT('01_Data'!R4:R1826) -> 16.167115 | G9: =MAX('01_Data'!R4:R1826) -> 0.22485582 | H9: =MIN('01_Data'!R4:R1826) -> -0.28555004 | I9: -0.67112245 | J9: =(C9-0.0319)/D9 -> 0.25190297 | K9: 0.34987146 | L9: 0.2002433
A10: OXY | B10: 1822 | C10: =AVERAGE('01_Data'!S4:S1826)*252 -> 0.024559709 | D10: =_xlfn.STDEV.S('01_Data'!S4:S1826)*SQRT(252) -> 0.57994572 | E10: =SKEW('01_Data'!S4:S1826) -> -4.0133523 | F10: =KURT('01_Data'!S4:S1826) -> 94.331669 | G10: =MAX('01_Data'!S4:S1826) -> 0.2904131 | H10: =MIN('01_Data'!S4:S1826) -> -0.73426089 | I10: -0.85853504 | J10: =(C10-0.0319)/D10 -> -0.012656859 | K10: -0.016709129 | L10: 0.028606629
A11: LNG | B11: 1822 | C11: =AVERAGE('01_Data'!T4:T1826)*252 -> 0.21944121 | D11: =_xlfn.STDEV.S('01_Data'!T4:T1826)*SQRT(252) -> 0.33640169 | E11: =SKEW('01_Data'!T4:T1826) -> -0.87082106 | F11: =KURT('01_Data'!T4:T1826) -> 9.5353371 | G11: =MAX('01_Data'!T4:T1826) -> 0.11607337 | H11: =MIN('01_Data'!T4:T1826) -> -0.19969472 | I11: -0.57472903 | J11: =(C11-0.0319)/D11 -> 0.55749186 | K11: 0.7750267 | L11: 0.38181694
A12: VG | B12: 298 | C12: =AVERAGE('01_Data'!U4:U1826)*252 -> -0.41097944 | D12: =_xlfn.STDEV.S('01_Data'!U4:U1826)*SQRT(252) -> 0.92446522 | E12: =SKEW('01_Data'!U4:U1826) -> -1.8553034 | F12: =KURT('01_Data'!U4:U1826) -> 13.183407 | G12: =MAX('01_Data'!U4:U1826) -> 0.19160885 | H12: =MIN('01_Data'!U4:U1826) -> -0.4470775 | I12: -0.72196286 | J12: =(C12-0.0319)/D12 -> -0.47906555 | K12: -0.60210494 | L12: -0.56925345
A13: FRO | B13: 1822 | C13: =AVERAGE('01_Data'!V4:V1826)*252 -> 0.33175048 | D13: =_xlfn.STDEV.S('01_Data'!V4:V1826)*SQRT(252) -> 0.53905521 | E13: =SKEW('01_Data'!V4:V1826) -> 0.12182438 | F13: =KURT('01_Data'!V4:V1826) -> 4.4543652 | G13: =MAX('01_Data'!V4:V1826) -> 0.24408426 | H13: =MIN('01_Data'!V4:V1826) -> -0.18510162 | I13: -0.52037234 | J13: =(C13-0.0319)/D13 -> 0.55625189 | K13: 0.81423359 | L13: 0.63752486
A14: STNG | B14: 1822 | C14: =AVERAGE('01_Data'!W4:W1826)*252 -> 0.21713811 | D14: =_xlfn.STDEV.S('01_Data'!W4:W1826)*SQRT(252) -> 0.55525292 | E14: =SKEW('01_Data'!W4:W1826) -> -0.049901623 | F14: =KURT('01_Data'!W4:W1826) -> 5.0414826 | G14: =MAX('01_Data'!W4:W1826) -> 0.24837037 | H14: =MIN('01_Data'!W4:W1826) -> -0.25222154 | I14: -0.7736644 | J14: =(C14-0.0319)/D14 -> 0.33361032 | K14: 0.47961125 | L14: 0.28066208
A15: ET | B15: 1822 | C15: =AVERAGE('01_Data'!X4:X1826)*252 -> 0.13744943 | D15: =_xlfn.STDEV.S('01_Data'!X4:X1826)*SQRT(252) -> 0.35810477 | E15: =SKEW('01_Data'!X4:X1826) -> -1.8935112 | F15: =KURT('01_Data'!X4:X1826) -> 30.802747 | G15: =MAX('01_Data'!X4:X1826) -> 0.17827097 | H15: =MIN('01_Data'!X4:X1826) -> -0.32594063 | I15: -0.68524815 | J15: =(C15-0.0319)/D15 -> 0.29474456 | K15: 0.39430343 | L15: 0.20058275
A16: BIL | B16: 1822 | C16: =AVERAGE('01_Data'!Y4:Y1826)*252 -> 0.025679323 | D16: =_xlfn.STDEV.S('01_Data'!Y4:Y1826)*SQRT(252) -> 0.0024986306 | E16: =SKEW('01_Data'!Y4:Y1826) -> 0.7955491 | F16: =KURT('01_Data'!Y4:Y1826) -> 1.1535796 | G16: =MAX('01_Data'!Y4:Y1826) -> 0.00076464479 | H16: =MIN('01_Data'!Y4:Y1826) -> -0.00032770895 | I16: -0.002085089 | J16: =(C16-0.0319)/D16 -> -2.4896346 | K16: -3.4291474 | L16: 12.315708
A20: SECTION B — EVENT-WINDOW STATISTICS
A21: DEF: Event-Window Stats
A22: Ann Mean Return and Ann Volatility use AVERAGEIFS/STDEV formulas referencing Tab 1 event IDs. Skewness, Kurtosis, Max, Min, Drawdown, Sortino, Calmar remain Python-computed (complex conditionals).
A23: Event 1: Pre-COVID (2019-01-01 to 2020-02-19)
A24: Ticker | B24: N | C24: Ann Mean Ret | D24: Ann Volatility | E24: Sharpe | F24: Skewness | G24: Excess Kurtosis | H24: Max Daily Ret | I24: Min Daily Ret | J24: Max Drawdown | K24: Sortino Ratio | L24: Calmar Ratio
A25: XOM | B25: 284 | C25: =AVERAGEIFS('01_Data'!P4:P1826,'01_Data'!BG4:BG1826,1)*252 -> -0.073669367 | D25: 0.18979737 | E25: =(C25-0.0319)/D25 -> -0.55622145 | F25: 0.057366072 | G25: 1.2672612 | H25: 0.044995772 | I25: -0.042083142 | J25: -0.25459068 | K25: -0.77167215 | L25: -0.28936368
A26: CVX | B26: 284 | C26: =AVERAGEIFS('01_Data'!Q4:Q1826,'01_Data'!BG4:BG1826,1)*252 -> 0.046049826 | D26: 0.18422521 | E26: =(C26-0.0319)/D26 -> 0.076807218 | F26: -0.24345305 | G26: 2.5848465 | H26: 0.045091191 | I26: -0.050712513 | J26: -0.1431127 | K26: 0.10678032 | L26: 0.32177259
A27: COP | B27: 284 | C27: =AVERAGEIFS('01_Data'!R4:R1826,'01_Data'!BG4:BG1826,1)*252 -> -0.03376955 | D27: 0.27519087 | E27: =(C27-0.0319)/D27 -> -0.23863274 | F27: 0.29729531 | G27: 2.2433211 | H27: 0.086647823 | I27: -0.057951891 | J27: -0.27914146 | K27: -0.34138932 | L27: -0.1209778
